<?xml version="1.0" ?>
<!-- =================================================================================== -->
<!-- |    This document was autogenerated by xacro from robotiq_85_gripper_standalone.urdf.xacro | -->
<!-- |    EDITING THIS FILE BY HAND IS NOT RECOMMENDED                                 | -->
<!-- =================================================================================== -->
<robot name="robotiq85_gripper" xmlns:drake="http://drake.mit.edu" xmlns:xacro="http://ros.org/wiki/xacro">
  <link name="robotiq_coupler_link">
    <visual>
      <geometry>
        <mesh filename="package://movo_description/meshes/manipulation/robotiq/visual/kinova_robotiq_coupler.obj"/>
      </geometry>
    </visual>
    <collision>
      <geometry>
        <mesh filename="package://movo_description/meshes/manipulation/robotiq/collision/kinova_robotiq_coupler.obj"/>
      </geometry>
    </collision>
    <inertial>
      <mass value="0.1"/>
      <origin xyz="0.0 0.0 0.0"/>
      <inertia ixx="0.000001" ixy="0.000000" ixz="0.000000" iyx="0.000000" iyy="0.000001" iyz="0.000000" izx="0.000000" izy="0.000000" izz="0.000001"/>
    </inertial>
  </link>
  <gazebo reference="robotiq_coupler_link">
    <implicitSpringDamper>1</implicitSpringDamper>
    <mu1>100000</mu1>
    <mu2>100000</mu2>
    <kp>100000000.0</kp>
    <kd>1.0</kd>
  </gazebo>
  <joint name="gripper_base_joint" type="fixed">
    <parent link="robotiq_coupler_link"/>
    <child link="gripper_base_link"/>
    <origin rpy="-1.570795 1.570795 0.0" xyz="0 0 -0.05105"/>
  </joint>
  <link name="gripper_base_link">
    <visual>
      <geometry>
        <mesh filename="package://movo_description/meshes/manipulation/robotiq/visual/robotiq_85_base_link.obj"/>
      </geometry>
    </visual>
    <collision>
      <geometry>
        <mesh filename="package://movo_description/meshes/manipulation/robotiq/collision/robotiq_85_base_link.obj"/>
      </geometry>
    </collision>
    <inertial>
      <mass value="0.636951"/>
      <origin xyz="0.0 0.0 0.0"/>
      <inertia ixx="0.000380" ixy="0.000000" ixz="0.000000" iyx="0.000000" iyy="0.001110" iyz="0.000000" izx="0.000000" izy="0.000000" izz="0.001171"/>
    </inertial>
  </link>
  <gazebo reference="gripper_base_link">
    <implicitSpringDamper>1</implicitSpringDamper>
    <mu1>100000</mu1>
    <mu2>100000</mu2>
    <kp>100000000.0</kp>
    <kd>1.0</kd>
  </gazebo>
  <joint name="gripper_finger1_joint" type="revolute">
    <parent link="gripper_base_link"/>
    <child link="gripper_finger1_knuckle_link"/>
    <axis xyz="0 0 1"/>
    <origin rpy="3.14159 0.0 0.0" xyz="0.05490451627 0.03060114443 0.0"/>
    <limit effort="1000" lower="0.0" upper="0.804" velocity="2.0"/>
  </joint>
  <joint name="gripper_finger2_joint" type="revolute">
    <parent link="gripper_base_link"/>
    <child link="gripper_finger2_knuckle_link"/>
    <axis xyz="0 0 1"/>
    <origin rpy="0.0 0.0 0.0" xyz="0.05490451627 -0.03060114443 0.0"/>
    <limit effort="1000" lower="-3.14" upper="3.14" velocity="100.0"/>
  </joint>
  <link name="gripper_finger1_knuckle_link">
    <visual>
      <geometry>
        <mesh filename="package://movo_description/meshes/manipulation/robotiq/visual/robotiq_85_knuckle_link.obj"/>
      </geometry>
    </visual>
    <collision>
      <geometry>
        <mesh filename="package://movo_description/meshes/manipulation/robotiq/collision/robotiq_85_knuckle_link.obj"/>
      </geometry>
    </collision>
    <inertial>
      <mass value="0.018491"/>
      <origin xyz="0.0 0.0 0.0"/>
      <inertia ixx="0.000009" ixy="-0.000001" ixz="0.000000" iyx="-0.000001" iyy="0.000001" iyz="0.000000" izx="0.000000" izy="0.000000" izz="0.000010"/>
    </inertial>
  </link>
  <gazebo reference="gripper_finger1_knuckle_link">
    <implicitSpringDamper>1</implicitSpringDamper>
    <mu1>100000</mu1>
    <mu2>100000</mu2>
    <kp>100000000.0</kp>
    <kd>1.0</kd>
  </gazebo>
  <link name="gripper_finger2_knuckle_link">
    <visual>
      <geometry>
        <mesh filename="package://movo_description/meshes/manipulation/robotiq/visual/robotiq_85_knuckle_link.obj"/>
      </geometry>
    </visual>
    <collision>
      <geometry>
        <mesh filename="package://movo_description/meshes/manipulation/robotiq/collision/robotiq_85_knuckle_link.obj"/>
      </geometry>
    </collision>
    <inertial>
      <mass value="0.018491"/>
      <origin xyz="0.0 0.0 0.0"/>
      <inertia ixx="0.000009" ixy="-0.000001" ixz="0.000000" iyx="-0.000001" iyy="0.000001" iyz="0.000000" izx="0.000000" izy="0.000000" izz="0.000010"/>
    </inertial>
  </link>
  <gazebo reference="gripper_finger2_knuckle_link">
    <implicitSpringDamper>1</implicitSpringDamper>
    <mu1>100000</mu1>
    <mu2>100000</mu2>
    <kp>100000000.0</kp>
    <kd>1.0</kd>
  </gazebo>
  <joint name="gripper_finger1_finger_joint" type="fixed">
    <parent link="gripper_finger1_knuckle_link"/>
    <child link="gripper_finger1_finger_link"/>
    <origin rpy="0 0 0" xyz="-0.00408552455 -0.03148604435 0.0"/>
  </joint>
  <joint name="gripper_finger2_finger_joint" type="fixed">
    <parent link="gripper_finger2_knuckle_link"/>
    <child link="gripper_finger2_finger_link"/>
    <origin rpy="0 0 0" xyz="-0.00408552455 -0.03148604435 0.0"/>
  </joint>
  <link name="gripper_finger1_finger_link">
    <visual>
      <geometry>
        <mesh filename="package://movo_description/meshes/manipulation/robotiq/visual/robotiq_85_finger_link.obj"/>
      </geometry>
    </visual>
    <collision>
      <geometry>
        <mesh filename="package://movo_description/meshes/manipulation/robotiq/collision/robotiq_85_finger_link.obj"/>
      </geometry>
    </collision>
    <inertial>
      <mass value="0.027309"/>
      <origin xyz="0.0 0.0 0.0"/>
      <inertia ixx="0.000003" ixy="-0.000002" ixz="0.000000" iyx="-0.000002" iyy="0.000021" iyz="0.000000" izx="0.000000" izy="0.000000" izz="0.000020"/>
    </inertial>
  </link>
  <gazebo reference="gripper_finger1_finger_link">
    <implicitSpringDamper>1</implicitSpringDamper>
    <mu1>100000</mu1>
    <mu2>100000</mu2>
    <kp>100000000.0</kp>
    <kd>1.0</kd>
  </gazebo>
  <link name="gripper_finger2_finger_link">
    <visual>
      <geometry>
        <mesh filename="package://movo_description/meshes/manipulation/robotiq/visual/robotiq_85_finger_link.obj"/>
      </geometry>
    </visual>
    <collision>
      <geometry>
        <mesh filename="package://movo_description/meshes/manipulation/robotiq/collision/robotiq_85_finger_link.obj"/>
      </geometry>
    </collision>
    <inertial>
      <mass value="0.027309"/>
      <origin xyz="0.0 0.0 0.0"/>
      <inertia ixx="0.000003" ixy="-0.000002" ixz="0.000000" iyx="-0.000002" iyy="0.000021" iyz="0.000000" izx="0.000000" izy="0.000000" izz="0.000020"/>
    </inertial>
  </link>
  <gazebo reference="gripper_finger2_finger_link">
    <implicitSpringDamper>1</implicitSpringDamper>
    <mu1>100000</mu1>
    <mu2>100000</mu2>
    <kp>100000000.0</kp>
    <kd>1.0</kd>
  </gazebo>
  <joint name="gripper_finger1_inner_knuckle_joint" type="revolute">
    <parent link="gripper_base_link"/>
    <child link="gripper_finger1_inner_knuckle_link"/>
    <axis xyz="0 0 1"/>
    <origin rpy="3.14159 0.0 0.0" xyz="0.06142 0.0127 0"/>
    <limit effort="0.1" lower="-3.14" upper="3.14" velocity="100.0"/>
  </joint>
  <joint name="gripper_finger2_inner_knuckle_joint" type="revolute">
    <parent link="gripper_base_link"/>
    <child link="gripper_finger2_inner_knuckle_link"/>
    <axis xyz="0 0 1"/>
    <origin rpy="0 0 0" xyz="0.06142 -0.0127 0"/>
    <limit effort="0.1" lower="-3.14" upper="3.14" velocity="100.0"/>
  </joint>
  <link name="gripper_finger1_inner_knuckle_link">
    <visual>
      <geometry>
        <mesh filename="package://movo_description/meshes/manipulation/robotiq/visual/robotiq_85_inner_knuckle_link.obj"/>
      </geometry>
    </visual>
    <!--
            <collision>
                <geometry>
                    <mesh filename="package://movo_description/meshes/manipulation/robotiq/collision/robotiq_85_inner_knuckle_link.obj"/>
                </geometry>
            </collision>
            -->
    <inertial>
      <mass value="0.029951"/>
      <origin xyz="0.0 0.0 0.0"/>
      <inertia ixx="0.000039" ixy="0.000000" ixz="0.000000" iyx="0.000000" iyy="0.000005" iyz="0.000000" izx="0.000000" izy="0.000000" izz="0.000035"/>
    </inertial>
  </link>
  <gazebo reference="gripper_finger1_inner_knuckle_link">
    <implicitSpringDamper>1</implicitSpringDamper>
    <mu1>100000</mu1>
    <mu2>100000</mu2>
    <kp>100000000.0</kp>
    <kd>1.0</kd>
  </gazebo>
  <link name="gripper_finger2_inner_knuckle_link">
    <visual>
      <geometry>
        <mesh filename="package://movo_description/meshes/manipulation/robotiq/visual/robotiq_85_inner_knuckle_link.obj"/>
      </geometry>
    </visual>
    <!--
            <collision>
                <geometry>
                    <mesh filename="package://movo_description/meshes/manipulation/robotiq/collision/robotiq_85_inner_knuckle_link.obj"/>
                </geometry>
            </collision>
            -->
    <inertial>
      <mass value="0.029951"/>
      <origin xyz="0.0 0.0 0.0"/>
      <inertia ixx="0.000039" ixy="0.000000" ixz="0.000000" iyx="0.000000" iyy="0.000005" iyz="0.000000" izx="0.000000" izy="0.000000" izz="0.000035"/>
    </inertial>
  </link>
  <gazebo reference="gripper_finger2_inner_knuckle_link">
    <implicitSpringDamper>1</implicitSpringDamper>
    <mu1>100000</mu1>
    <mu2>100000</mu2>
    <kp>100000000.0</kp>
    <kd>1.0</kd>
  </gazebo>
  <joint name="gripper_finger1_finger_tip_joint" type="revolute">
    <parent link="gripper_finger1_inner_knuckle_link"/>
    <child link="gripper_finger1_finger_tip_link"/>
    <axis xyz="0 0 1"/>
    <origin rpy="0.0 0.0 0.0" xyz="0.04303959807 -0.03759940821 0.0"/>
    <limit effort="0.1" lower="-3.14" upper="3.14" velocity="100.0"/>
  </joint>
  <joint name="gripper_finger2_finger_tip_joint" type="revolute">
    <parent link="gripper_finger2_inner_knuckle_link"/>
    <child link="gripper_finger2_finger_tip_link"/>
    <axis xyz="0 0 1"/>
    <origin rpy="0.0 0.0 0.0" xyz="0.04303959807 -0.03759940821  0.0"/>
    <limit effort="0.1" lower="-3.14" upper="3.14" velocity="100.0"/>
  </joint>
  <link name="gripper_finger1_finger_tip_link">
    <visual>
      <geometry>
        <mesh filename="package://movo_description/meshes/manipulation/robotiq/visual/robotiq_85_finger_tip_link.obj"/>
      </geometry>
    </visual>
    <collision>
      <!-- box for finger tip computed by measuring in blender -->
      <origin xyz="0.02575 0.004375 0"/>
      <geometry>
        <box size="0.0375 0.00675 0.022"/>
      </geometry>
      <drake:proximity_properties>
        <drake:mu_static value="1.0"/>
        <drake:mu_dynamic value="1.0"/>
        <drake:hydroelastic_modulus value="1.0e5"/>
        <drake:hunt_crossley_dissipation value="10.0"/>
        <drake:compliant_hydroelastic/>
      </drake:proximity_properties>
      <!--
                  <geometry>
                      <mesh filename="package://movo_description/meshes/manipulation/robotiq/collision/robotiq_85_finger_tip_link.obj"/>
                  </geometry>
                -->
    </collision>
    <inertial>
      <mass value="0.019555"/>
      <origin xyz="0.0 0.0 0.0"/>
      <inertia ixx="0.000002" ixy="0.000000" ixz="0.000000" iyx="0.000000" iyy="0.000005" iyz="0.000000" izx="0.000000" izy="0.000000" izz="0.000006"/>
    </inertial>
  </link>
  <gazebo reference="gripper_finger1_finger_tip_link">
    <implicitSpringDamper>1</implicitSpringDamper>
    <mu1>100000</mu1>
    <mu2>100000</mu2>
    <kp>100000000.0</kp>
    <kd>1.0</kd>
  </gazebo>
  <link name="gripper_finger2_finger_tip_link">
    <visual>
      <geometry>
        <mesh filename="package://movo_description/meshes/manipulation/robotiq/visual/robotiq_85_finger_tip_link.obj"/>
      </geometry>
    </visual>
    <collision>
      <!-- box for finger tip computed by measuring in blender -->
      <origin xyz="0.02575 0.004375 0"/>
      <geometry>
        <box size="0.0375 0.00675 0.022"/>
      </geometry>
      <drake:proximity_properties>
        <drake:mu_static value="1.0"/>
        <drake:mu_dynamic value="1.0"/>
        <drake:hydroelastic_modulus value="1.0e5"/>
        <drake:hunt_crossley_dissipation value="10.0"/>
        <drake:compliant_hydroelastic/>
      </drake:proximity_properties>
      <!--
                  <geometry>
                      <mesh filename="package://movo_description/meshes/manipulation/robotiq/collision/robotiq_85_finger_tip_link.obj"/>
                  </geometry>
                -->
    </collision>
    <inertial>
      <mass value="0.019555"/>
      <origin xyz="0.0 0.0 0.0"/>
      <inertia ixx="0.000002" ixy="0.000000" ixz="0.000000" iyx="0.000000" iyy="0.000005" iyz="0.000000" izx="0.000000" izy="0.000000" izz="0.000006"/>
    </inertial>
  </link>
  <gazebo reference="gripper_finger2_finger_tip_link">
    <implicitSpringDamper>1</implicitSpringDamper>
    <mu1>100000</mu1>
    <mu2>100000</mu2>
    <kp>100000000.0</kp>
    <kd>1.0</kd>
  </gazebo>
  <gazebo>
    <!-- loading plugin: mimic joints works in gazebo now -->
    <plugin filename="libroboticsgroup_gazebo_mimic_joint_plugin.so" name="mimic_robotiq_85_1">
      <joint>gripper_finger1_joint</joint>
      <mimicJoint>gripper_finger2_joint</mimicJoint>
      <!--multiplier>1.0</multiplier>
                <offset>0.0</offset-->
    </plugin>
    <plugin filename="libroboticsgroup_gazebo_mimic_joint_plugin.so" name="mimic_robotiq_85_2">
      <joint>gripper_finger1_joint</joint>
      <mimicJoint>gripper_finger2_inner_knuckle_joint</mimicJoint>
      <!--multiplier>1.0</multiplier>
                <offset>0.0</offset-->
    </plugin>
    <plugin filename="libroboticsgroup_gazebo_mimic_joint_plugin.so" name="mimic_robotiq_85_3">
      <joint>gripper_finger1_joint</joint>
      <mimicJoint>gripper_finger1_inner_knuckle_joint</mimicJoint>
      <!--multiplier>1.0</multiplier>
                <offset>0.0</offset-->
    </plugin>
    <plugin filename="libroboticsgroup_gazebo_mimic_joint_plugin.so" name="mimic_robotiq_85_4">
      <joint>gripper_finger1_joint</joint>
      <mimicJoint>gripper_finger1_finger_tip_joint</mimicJoint>
      <multiplier>-1.0</multiplier>
      <offset>0.0</offset>
    </plugin>
    <plugin filename="libroboticsgroup_gazebo_mimic_joint_plugin.so" name="mimic_robotiq_85_5">
      <joint>gripper_finger1_joint</joint>
      <mimicJoint>gripper_finger2_finger_tip_joint</mimicJoint>
      <multiplier>-1.0</multiplier>
      <offset>0.0</offset>
    </plugin>
  </gazebo>
  <drake:collision_filter_group name="finger_1">
    <drake:member link="gripper_finger1_finger_link"/>
    <drake:member link="gripper_finger1_inner_knuckle_link"/>
    <drake:member link="gripper_finger1_knuckle_link"/>
    <drake:member link="gripper_finger1_finger_tip_link"/>
    <drake:ignored_collision_filter_group name="finger_1"/>
  </drake:collision_filter_group>
  <drake:collision_filter_group name="finger_2">
    <drake:member link="gripper_finger2_finger_link"/>
    <drake:member link="gripper_finger2_inner_knuckle_link"/>
    <drake:member link="gripper_finger2_knuckle_link"/>
    <drake:member link="gripper_finger2_finger_tip_link"/>
    <drake:ignored_collision_filter_group name="finger_2"/>
  </drake:collision_filter_group>
</robot>

